Setting up a new session...
Traceback (most recent call last):
  File "/apps/anaconda3/lib/python3.7/site-packages/urllib3/connection.py", line 157, in _new_conn
    (self._dns_host, self.port), self.timeout, **extra_kw
  File "/apps/anaconda3/lib/python3.7/site-packages/urllib3/util/connection.py", line 84, in create_connection
    raise err
  File "/apps/anaconda3/lib/python3.7/site-packages/urllib3/util/connection.py", line 74, in create_connection
    sock.connect(sa)
ConnectionRefusedError: [Errno 111] Connection refused

During handling of the above exception, another exception occurred:

Traceback (most recent call last):
  File "/apps/anaconda3/lib/python3.7/site-packages/urllib3/connectionpool.py", line 672, in urlopen
    chunked=chunked,
  File "/apps/anaconda3/lib/python3.7/site-packages/urllib3/connectionpool.py", line 387, in _make_request
    conn.request(method, url, **httplib_request_kw)
  File "/apps/anaconda3/lib/python3.7/http/client.py", line 1252, in request
    self._send_request(method, url, body, headers, encode_chunked)
  File "/apps/anaconda3/lib/python3.7/http/client.py", line 1298, in _send_request
    self.endheaders(body, encode_chunked=encode_chunked)
  File "/apps/anaconda3/lib/python3.7/http/client.py", line 1247, in endheaders
    self._send_output(message_body, encode_chunked=encode_chunked)
  File "/apps/anaconda3/lib/python3.7/http/client.py", line 1026, in _send_output
    self.send(msg)
  File "/apps/anaconda3/lib/python3.7/http/client.py", line 966, in send
    self.connect()
  File "/apps/anaconda3/lib/python3.7/site-packages/urllib3/connection.py", line 184, in connect
    conn = self._new_conn()
  File "/apps/anaconda3/lib/python3.7/site-packages/urllib3/connection.py", line 169, in _new_conn
    self, "Failed to establish a new connection: %s" % e
urllib3.exceptions.NewConnectionError: <urllib3.connection.HTTPConnection object at 0x2aab1a243310>: Failed to establish a new connection: [Errno 111] Connection refused

During handling of the above exception, another exception occurred:

Traceback (most recent call last):
  File "/apps/anaconda3/lib/python3.7/site-packages/requests/adapters.py", line 449, in send
    timeout=timeout
  File "/apps/anaconda3/lib/python3.7/site-packages/urllib3/connectionpool.py", line 720, in urlopen
    method, url, error=e, _pool=self, _stacktrace=sys.exc_info()[2]
  File "/apps/anaconda3/lib/python3.7/site-packages/urllib3/util/retry.py", line 436, in increment
    raise MaxRetryError(_pool, url, error or ResponseError(cause))
urllib3.exceptions.MaxRetryError: HTTPConnectionPool(host='localhost', port=8097): Max retries exceeded with url: /env/main (Caused by NewConnectionError('<urllib3.connection.HTTPConnection object at 0x2aab1a243310>: Failed to establish a new connection: [Errno 111] Connection refused'))

During handling of the above exception, another exception occurred:

Traceback (most recent call last):
  File "/home/FYP/awang007/.local/lib/python3.7/site-packages/visdom/__init__.py", line 695, in _send
    data=json.dumps(msg),
  File "/home/FYP/awang007/.local/lib/python3.7/site-packages/visdom/__init__.py", line 656, in _handle_post
    r = self.session.post(url, data=data)
  File "/apps/anaconda3/lib/python3.7/site-packages/requests/sessions.py", line 581, in post
    return self.request('POST', url, data=data, json=json, **kwargs)
  File "/apps/anaconda3/lib/python3.7/site-packages/requests/sessions.py", line 533, in request
    resp = self.send(prep, **send_kwargs)
  File "/apps/anaconda3/lib/python3.7/site-packages/requests/sessions.py", line 646, in send
    r = adapter.send(request, **kwargs)
  File "/apps/anaconda3/lib/python3.7/site-packages/requests/adapters.py", line 516, in send
    raise ConnectionError(e, request=request)
requests.exceptions.ConnectionError: HTTPConnectionPool(host='localhost', port=8097): Max retries exceeded with url: /env/main (Caused by NewConnectionError('<urllib3.connection.HTTPConnection object at 0x2aab1a243310>: Failed to establish a new connection: [Errno 111] Connection refused'))
[Errno 111] Connection refused
on_close() takes 1 positional argument but 3 were given
